============================= test session starts ==============================
platform linux -- Python 3.9.18, pytest-7.4.2, pluggy-1.3.0
rootdir: /app/web
collected 8 items

test_all_pages.py EEEEEEEE                                               [100%]

==================================== ERRORS ====================================
__________ ERROR at setup of test_page_loads[https://thaersaidi.net] ___________

    @pytest.fixture
    def browser():
        # Setup
        options = webdriver.ChromeOptions()
>       driver = webdriver.Chrome(service=Service(ChromeDriverManager().install()), options=options)

test_all_pages.py:28: 
_ _ _ _ _ _ _ _ _ _ _ _ _ _ _ _ _ _ _ _ _ _ _ _ _ _ _ _ _ _ _ _ _ _ _ _ _ _ _ _ 
/usr/local/lib/python3.9/site-packages/selenium/webdriver/chrome/webdriver.py:70: in __init__
    super(WebDriver, self).__init__(DesiredCapabilities.CHROME['browserName'], "goog",
/usr/local/lib/python3.9/site-packages/selenium/webdriver/chromium/webdriver.py:90: in __init__
    self.service.start()
/usr/local/lib/python3.9/site-packages/selenium/webdriver/common/service.py:98: in start
    self.assert_process_still_running()
_ _ _ _ _ _ _ _ _ _ _ _ _ _ _ _ _ _ _ _ _ _ _ _ _ _ _ _ _ _ _ _ _ _ _ _ _ _ _ _ 

self = <selenium.webdriver.chrome.service.Service object at 0x7fe725894a30>

    def assert_process_still_running(self):
        return_code = self.process.poll()
        if return_code:
>           raise WebDriverException(
                'Service %s unexpectedly exited. Status code was: %s'
                % (self.path, return_code)
            )
E           selenium.common.exceptions.WebDriverException: Message: Service /root/.wdm/drivers/chromedriver/linux64/114.0.5735.90/chromedriver unexpectedly exited. Status code was: 127

/usr/local/lib/python3.9/site-packages/selenium/webdriver/common/service.py:110: WebDriverException
---------------------------- Captured stderr setup -----------------------------


====== WebDriver manager ======
Could not get version for google-chrome with the any command: google-chrome --version || google-chrome-stable --version
Current google-chrome version is UNKNOWN
Get LATEST chromedriver version for UNKNOWN google-chrome
Driver [/root/.wdm/drivers/chromedriver/linux64/114.0.5735.90/chromedriver] found in cache
------------------------------ Captured log setup ------------------------------
INFO     WDM:logger.py:26 

INFO     WDM:logger.py:26 ====== WebDriver manager ======
INFO     WDM:logger.py:26 Could not get version for google-chrome with the any command: google-chrome --version || google-chrome-stable --version
INFO     WDM:logger.py:26 Current google-chrome version is UNKNOWN
INFO     WDM:logger.py:26 Get LATEST chromedriver version for UNKNOWN google-chrome
INFO     WDM:logger.py:26 Driver [/root/.wdm/drivers/chromedriver/linux64/114.0.5735.90/chromedriver] found in cache
_____ ERROR at setup of test_page_loads[https://thaersaidi.net/education] ______

    @pytest.fixture
    def browser():
        # Setup
        options = webdriver.ChromeOptions()
>       driver = webdriver.Chrome(service=Service(ChromeDriverManager().install()), options=options)

test_all_pages.py:28: 
_ _ _ _ _ _ _ _ _ _ _ _ _ _ _ _ _ _ _ _ _ _ _ _ _ _ _ _ _ _ _ _ _ _ _ _ _ _ _ _ 
/usr/local/lib/python3.9/site-packages/selenium/webdriver/chrome/webdriver.py:70: in __init__
    super(WebDriver, self).__init__(DesiredCapabilities.CHROME['browserName'], "goog",
/usr/local/lib/python3.9/site-packages/selenium/webdriver/chromium/webdriver.py:90: in __init__
    self.service.start()
/usr/local/lib/python3.9/site-packages/selenium/webdriver/common/service.py:98: in start
    self.assert_process_still_running()
_ _ _ _ _ _ _ _ _ _ _ _ _ _ _ _ _ _ _ _ _ _ _ _ _ _ _ _ _ _ _ _ _ _ _ _ _ _ _ _ 

self = <selenium.webdriver.chrome.service.Service object at 0x7fe725829df0>

    def assert_process_still_running(self):
        return_code = self.process.poll()
        if return_code:
>           raise WebDriverException(
                'Service %s unexpectedly exited. Status code was: %s'
                % (self.path, return_code)
            )
E           selenium.common.exceptions.WebDriverException: Message: Service /root/.wdm/drivers/chromedriver/linux64/114.0.5735.90/chromedriver unexpectedly exited. Status code was: 127

/usr/local/lib/python3.9/site-packages/selenium/webdriver/common/service.py:110: WebDriverException
---------------------------- Captured stderr setup -----------------------------


====== WebDriver manager ======
Could not get version for google-chrome with the any command: google-chrome --version || google-chrome-stable --version
Current google-chrome version is UNKNOWN
Get LATEST chromedriver version for UNKNOWN google-chrome
Driver [/root/.wdm/drivers/chromedriver/linux64/114.0.5735.90/chromedriver] found in cache
------------------------------ Captured log setup ------------------------------
INFO     WDM:logger.py:26 

INFO     WDM:logger.py:26 ====== WebDriver manager ======
INFO     WDM:logger.py:26 Could not get version for google-chrome with the any command: google-chrome --version || google-chrome-stable --version
INFO     WDM:logger.py:26 Current google-chrome version is UNKNOWN
INFO     WDM:logger.py:26 Get LATEST chromedriver version for UNKNOWN google-chrome
INFO     WDM:logger.py:26 Driver [/root/.wdm/drivers/chromedriver/linux64/114.0.5735.90/chromedriver] found in cache
_____ ERROR at setup of test_page_loads[https://thaersaidi.net/employment] _____

    @pytest.fixture
    def browser():
        # Setup
        options = webdriver.ChromeOptions()
>       driver = webdriver.Chrome(service=Service(ChromeDriverManager().install()), options=options)

test_all_pages.py:28: 
_ _ _ _ _ _ _ _ _ _ _ _ _ _ _ _ _ _ _ _ _ _ _ _ _ _ _ _ _ _ _ _ _ _ _ _ _ _ _ _ 
/usr/local/lib/python3.9/site-packages/selenium/webdriver/chrome/webdriver.py:70: in __init__
    super(WebDriver, self).__init__(DesiredCapabilities.CHROME['browserName'], "goog",
/usr/local/lib/python3.9/site-packages/selenium/webdriver/chromium/webdriver.py:90: in __init__
    self.service.start()
/usr/local/lib/python3.9/site-packages/selenium/webdriver/common/service.py:98: in start
    self.assert_process_still_running()
_ _ _ _ _ _ _ _ _ _ _ _ _ _ _ _ _ _ _ _ _ _ _ _ _ _ _ _ _ _ _ _ _ _ _ _ _ _ _ _ 

self = <selenium.webdriver.chrome.service.Service object at 0x7fe7257e7d90>

    def assert_process_still_running(self):
        return_code = self.process.poll()
        if return_code:
>           raise WebDriverException(
                'Service %s unexpectedly exited. Status code was: %s'
                % (self.path, return_code)
            )
E           selenium.common.exceptions.WebDriverException: Message: Service /root/.wdm/drivers/chromedriver/linux64/114.0.5735.90/chromedriver unexpectedly exited. Status code was: 127

/usr/local/lib/python3.9/site-packages/selenium/webdriver/common/service.py:110: WebDriverException
---------------------------- Captured stderr setup -----------------------------


====== WebDriver manager ======
Could not get version for google-chrome with the any command: google-chrome --version || google-chrome-stable --version
Current google-chrome version is UNKNOWN
Get LATEST chromedriver version for UNKNOWN google-chrome
Driver [/root/.wdm/drivers/chromedriver/linux64/114.0.5735.90/chromedriver] found in cache
------------------------------ Captured log setup ------------------------------
INFO     WDM:logger.py:26 

INFO     WDM:logger.py:26 ====== WebDriver manager ======
INFO     WDM:logger.py:26 Could not get version for google-chrome with the any command: google-chrome --version || google-chrome-stable --version
INFO     WDM:logger.py:26 Current google-chrome version is UNKNOWN
INFO     WDM:logger.py:26 Get LATEST chromedriver version for UNKNOWN google-chrome
INFO     WDM:logger.py:26 Driver [/root/.wdm/drivers/chromedriver/linux64/114.0.5735.90/chromedriver] found in cache
_____ ERROR at setup of test_page_loads[https://thaersaidi.net/interests] ______

    @pytest.fixture
    def browser():
        # Setup
        options = webdriver.ChromeOptions()
>       driver = webdriver.Chrome(service=Service(ChromeDriverManager().install()), options=options)

test_all_pages.py:28: 
_ _ _ _ _ _ _ _ _ _ _ _ _ _ _ _ _ _ _ _ _ _ _ _ _ _ _ _ _ _ _ _ _ _ _ _ _ _ _ _ 
/usr/local/lib/python3.9/site-packages/selenium/webdriver/chrome/webdriver.py:70: in __init__
    super(WebDriver, self).__init__(DesiredCapabilities.CHROME['browserName'], "goog",
/usr/local/lib/python3.9/site-packages/selenium/webdriver/chromium/webdriver.py:90: in __init__
    self.service.start()
/usr/local/lib/python3.9/site-packages/selenium/webdriver/common/service.py:98: in start
    self.assert_process_still_running()
_ _ _ _ _ _ _ _ _ _ _ _ _ _ _ _ _ _ _ _ _ _ _ _ _ _ _ _ _ _ _ _ _ _ _ _ _ _ _ _ 

self = <selenium.webdriver.chrome.service.Service object at 0x7fe7257ee1f0>

    def assert_process_still_running(self):
        return_code = self.process.poll()
        if return_code:
>           raise WebDriverException(
                'Service %s unexpectedly exited. Status code was: %s'
                % (self.path, return_code)
            )
E           selenium.common.exceptions.WebDriverException: Message: Service /root/.wdm/drivers/chromedriver/linux64/114.0.5735.90/chromedriver unexpectedly exited. Status code was: 127

/usr/local/lib/python3.9/site-packages/selenium/webdriver/common/service.py:110: WebDriverException
---------------------------- Captured stderr setup -----------------------------


====== WebDriver manager ======
Could not get version for google-chrome with the any command: google-chrome --version || google-chrome-stable --version
Current google-chrome version is UNKNOWN
Get LATEST chromedriver version for UNKNOWN google-chrome
Driver [/root/.wdm/drivers/chromedriver/linux64/114.0.5735.90/chromedriver] found in cache
------------------------------ Captured log setup ------------------------------
INFO     WDM:logger.py:26 

INFO     WDM:logger.py:26 ====== WebDriver manager ======
INFO     WDM:logger.py:26 Could not get version for google-chrome with the any command: google-chrome --version || google-chrome-stable --version
INFO     WDM:logger.py:26 Current google-chrome version is UNKNOWN
INFO     WDM:logger.py:26 Get LATEST chromedriver version for UNKNOWN google-chrome
INFO     WDM:logger.py:26 Driver [/root/.wdm/drivers/chromedriver/linux64/114.0.5735.90/chromedriver] found in cache
_____ ERROR at setup of test_page_loads[https://thaersaidi.net/languages] ______

    @pytest.fixture
    def browser():
        # Setup
        options = webdriver.ChromeOptions()
>       driver = webdriver.Chrome(service=Service(ChromeDriverManager().install()), options=options)

test_all_pages.py:28: 
_ _ _ _ _ _ _ _ _ _ _ _ _ _ _ _ _ _ _ _ _ _ _ _ _ _ _ _ _ _ _ _ _ _ _ _ _ _ _ _ 
/usr/local/lib/python3.9/site-packages/selenium/webdriver/chrome/webdriver.py:70: in __init__
    super(WebDriver, self).__init__(DesiredCapabilities.CHROME['browserName'], "goog",
/usr/local/lib/python3.9/site-packages/selenium/webdriver/chromium/webdriver.py:90: in __init__
    self.service.start()
/usr/local/lib/python3.9/site-packages/selenium/webdriver/common/service.py:98: in start
    self.assert_process_still_running()
_ _ _ _ _ _ _ _ _ _ _ _ _ _ _ _ _ _ _ _ _ _ _ _ _ _ _ _ _ _ _ _ _ _ _ _ _ _ _ _ 

self = <selenium.webdriver.chrome.service.Service object at 0x7fe7257d39a0>

    def assert_process_still_running(self):
        return_code = self.process.poll()
        if return_code:
>           raise WebDriverException(
                'Service %s unexpectedly exited. Status code was: %s'
                % (self.path, return_code)
            )
E           selenium.common.exceptions.WebDriverException: Message: Service /root/.wdm/drivers/chromedriver/linux64/114.0.5735.90/chromedriver unexpectedly exited. Status code was: 127

/usr/local/lib/python3.9/site-packages/selenium/webdriver/common/service.py:110: WebDriverException
---------------------------- Captured stderr setup -----------------------------


====== WebDriver manager ======
Could not get version for google-chrome with the any command: google-chrome --version || google-chrome-stable --version
Current google-chrome version is UNKNOWN
Get LATEST chromedriver version for UNKNOWN google-chrome
Driver [/root/.wdm/drivers/chromedriver/linux64/114.0.5735.90/chromedriver] found in cache
------------------------------ Captured log setup ------------------------------
INFO     WDM:logger.py:26 

INFO     WDM:logger.py:26 ====== WebDriver manager ======
INFO     WDM:logger.py:26 Could not get version for google-chrome with the any command: google-chrome --version || google-chrome-stable --version
INFO     WDM:logger.py:26 Current google-chrome version is UNKNOWN
INFO     WDM:logger.py:26 Get LATEST chromedriver version for UNKNOWN google-chrome
INFO     WDM:logger.py:26 Driver [/root/.wdm/drivers/chromedriver/linux64/114.0.5735.90/chromedriver] found in cache
_______ ERROR at setup of test_page_loads[https://thaersaidi.net/skills] _______

    @pytest.fixture
    def browser():
        # Setup
        options = webdriver.ChromeOptions()
>       driver = webdriver.Chrome(service=Service(ChromeDriverManager().install()), options=options)

test_all_pages.py:28: 
_ _ _ _ _ _ _ _ _ _ _ _ _ _ _ _ _ _ _ _ _ _ _ _ _ _ _ _ _ _ _ _ _ _ _ _ _ _ _ _ 
/usr/local/lib/python3.9/site-packages/selenium/webdriver/chrome/webdriver.py:70: in __init__
    super(WebDriver, self).__init__(DesiredCapabilities.CHROME['browserName'], "goog",
/usr/local/lib/python3.9/site-packages/selenium/webdriver/chromium/webdriver.py:90: in __init__
    self.service.start()
/usr/local/lib/python3.9/site-packages/selenium/webdriver/common/service.py:98: in start
    self.assert_process_still_running()
_ _ _ _ _ _ _ _ _ _ _ _ _ _ _ _ _ _ _ _ _ _ _ _ _ _ _ _ _ _ _ _ _ _ _ _ _ _ _ _ 

self = <selenium.webdriver.chrome.service.Service object at 0x7fe725894ca0>

    def assert_process_still_running(self):
        return_code = self.process.poll()
        if return_code:
>           raise WebDriverException(
                'Service %s unexpectedly exited. Status code was: %s'
                % (self.path, return_code)
            )
E           selenium.common.exceptions.WebDriverException: Message: Service /root/.wdm/drivers/chromedriver/linux64/114.0.5735.90/chromedriver unexpectedly exited. Status code was: 127

/usr/local/lib/python3.9/site-packages/selenium/webdriver/common/service.py:110: WebDriverException
---------------------------- Captured stderr setup -----------------------------


====== WebDriver manager ======
Could not get version for google-chrome with the any command: google-chrome --version || google-chrome-stable --version
Current google-chrome version is UNKNOWN
Get LATEST chromedriver version for UNKNOWN google-chrome
Driver [/root/.wdm/drivers/chromedriver/linux64/114.0.5735.90/chromedriver] found in cache
------------------------------ Captured log setup ------------------------------
INFO     WDM:logger.py:26 

INFO     WDM:logger.py:26 ====== WebDriver manager ======
INFO     WDM:logger.py:26 Could not get version for google-chrome with the any command: google-chrome --version || google-chrome-stable --version
INFO     WDM:logger.py:26 Current google-chrome version is UNKNOWN
INFO     WDM:logger.py:26 Get LATEST chromedriver version for UNKNOWN google-chrome
INFO     WDM:logger.py:26 Driver [/root/.wdm/drivers/chromedriver/linux64/114.0.5735.90/chromedriver] found in cache
_____ ERROR at setup of test_page_loads[https://thaersaidi.net/references] _____

    @pytest.fixture
    def browser():
        # Setup
        options = webdriver.ChromeOptions()
>       driver = webdriver.Chrome(service=Service(ChromeDriverManager().install()), options=options)

test_all_pages.py:28: 
_ _ _ _ _ _ _ _ _ _ _ _ _ _ _ _ _ _ _ _ _ _ _ _ _ _ _ _ _ _ _ _ _ _ _ _ _ _ _ _ 
/usr/local/lib/python3.9/site-packages/selenium/webdriver/chrome/webdriver.py:70: in __init__
    super(WebDriver, self).__init__(DesiredCapabilities.CHROME['browserName'], "goog",
/usr/local/lib/python3.9/site-packages/selenium/webdriver/chromium/webdriver.py:90: in __init__
    self.service.start()
/usr/local/lib/python3.9/site-packages/selenium/webdriver/common/service.py:98: in start
    self.assert_process_still_running()
_ _ _ _ _ _ _ _ _ _ _ _ _ _ _ _ _ _ _ _ _ _ _ _ _ _ _ _ _ _ _ _ _ _ _ _ _ _ _ _ 

self = <selenium.webdriver.chrome.service.Service object at 0x7fe7257fbaf0>

    def assert_process_still_running(self):
        return_code = self.process.poll()
        if return_code:
>           raise WebDriverException(
                'Service %s unexpectedly exited. Status code was: %s'
                % (self.path, return_code)
            )
E           selenium.common.exceptions.WebDriverException: Message: Service /root/.wdm/drivers/chromedriver/linux64/114.0.5735.90/chromedriver unexpectedly exited. Status code was: 127

/usr/local/lib/python3.9/site-packages/selenium/webdriver/common/service.py:110: WebDriverException
---------------------------- Captured stderr setup -----------------------------


====== WebDriver manager ======
Could not get version for google-chrome with the any command: google-chrome --version || google-chrome-stable --version
Current google-chrome version is UNKNOWN
Get LATEST chromedriver version for UNKNOWN google-chrome
Driver [/root/.wdm/drivers/chromedriver/linux64/114.0.5735.90/chromedriver] found in cache
------------------------------ Captured log setup ------------------------------
INFO     WDM:logger.py:26 

INFO     WDM:logger.py:26 ====== WebDriver manager ======
INFO     WDM:logger.py:26 Could not get version for google-chrome with the any command: google-chrome --version || google-chrome-stable --version
INFO     WDM:logger.py:26 Current google-chrome version is UNKNOWN
INFO     WDM:logger.py:26 Get LATEST chromedriver version for UNKNOWN google-chrome
INFO     WDM:logger.py:26 Driver [/root/.wdm/drivers/chromedriver/linux64/114.0.5735.90/chromedriver] found in cache
________ ERROR at setup of test_page_loads[https://thaersaidi.net/ask] _________

    @pytest.fixture
    def browser():
        # Setup
        options = webdriver.ChromeOptions()
>       driver = webdriver.Chrome(service=Service(ChromeDriverManager().install()), options=options)

test_all_pages.py:28: 
_ _ _ _ _ _ _ _ _ _ _ _ _ _ _ _ _ _ _ _ _ _ _ _ _ _ _ _ _ _ _ _ _ _ _ _ _ _ _ _ 
/usr/local/lib/python3.9/site-packages/selenium/webdriver/chrome/webdriver.py:70: in __init__
    super(WebDriver, self).__init__(DesiredCapabilities.CHROME['browserName'], "goog",
/usr/local/lib/python3.9/site-packages/selenium/webdriver/chromium/webdriver.py:90: in __init__
    self.service.start()
/usr/local/lib/python3.9/site-packages/selenium/webdriver/common/service.py:98: in start
    self.assert_process_still_running()
_ _ _ _ _ _ _ _ _ _ _ _ _ _ _ _ _ _ _ _ _ _ _ _ _ _ _ _ _ _ _ _ _ _ _ _ _ _ _ _ 

self = <selenium.webdriver.chrome.service.Service object at 0x7fe726480f70>

    def assert_process_still_running(self):
        return_code = self.process.poll()
        if return_code:
>           raise WebDriverException(
                'Service %s unexpectedly exited. Status code was: %s'
                % (self.path, return_code)
            )
E           selenium.common.exceptions.WebDriverException: Message: Service /root/.wdm/drivers/chromedriver/linux64/114.0.5735.90/chromedriver unexpectedly exited. Status code was: 127

/usr/local/lib/python3.9/site-packages/selenium/webdriver/common/service.py:110: WebDriverException
---------------------------- Captured stderr setup -----------------------------


====== WebDriver manager ======
Could not get version for google-chrome with the any command: google-chrome --version || google-chrome-stable --version
Current google-chrome version is UNKNOWN
Get LATEST chromedriver version for UNKNOWN google-chrome
Driver [/root/.wdm/drivers/chromedriver/linux64/114.0.5735.90/chromedriver] found in cache
------------------------------ Captured log setup ------------------------------
INFO     WDM:logger.py:26 

INFO     WDM:logger.py:26 ====== WebDriver manager ======
INFO     WDM:logger.py:26 Could not get version for google-chrome with the any command: google-chrome --version || google-chrome-stable --version
INFO     WDM:logger.py:26 Current google-chrome version is UNKNOWN
INFO     WDM:logger.py:26 Get LATEST chromedriver version for UNKNOWN google-chrome
INFO     WDM:logger.py:26 Driver [/root/.wdm/drivers/chromedriver/linux64/114.0.5735.90/chromedriver] found in cache
=============================== warnings summary ===============================
../../usr/local/lib/python3.9/site-packages/selenium/webdriver/remote/remote_connection.py:24
  /usr/local/lib/python3.9/site-packages/selenium/webdriver/remote/remote_connection.py:24: DeprecationWarning: 'urllib3[secure]' extra is deprecated and will be removed in a future release of urllib3 2.x. Read more in this issue: https://github.com/urllib3/urllib3/issues/2680
    import urllib3

-- Docs: https://docs.pytest.org/en/stable/how-to/capture-warnings.html
=========================== short test summary info ============================
ERROR test_all_pages.py::test_page_loads[https://thaersaidi.net] - selenium.c...
ERROR test_all_pages.py::test_page_loads[https://thaersaidi.net/education] - ...
ERROR test_all_pages.py::test_page_loads[https://thaersaidi.net/employment]
ERROR test_all_pages.py::test_page_loads[https://thaersaidi.net/interests] - ...
ERROR test_all_pages.py::test_page_loads[https://thaersaidi.net/languages] - ...
ERROR test_all_pages.py::test_page_loads[https://thaersaidi.net/skills] - sel...
ERROR test_all_pages.py::test_page_loads[https://thaersaidi.net/references]
ERROR test_all_pages.py::test_page_loads[https://thaersaidi.net/ask] - seleni...
========================= 1 warning, 8 errors in 7.10s =========================
